<?xml version="1.0" ?>
<robot name="tas_car"
    xmlns:xacro="http://www.ros.org/wiki/xacro">

    <!-- Wheel Joints  -->
    <joint name="l_f_wheel_joint" type="continuous">
        <axis rpy="0 0 0" xyz="0 0 1"/>
        <origin rpy="1.570796325 0 3.14159265" xyz="0 0 0"/>
        <parent link="l_ack_link"/>
        <child link="l_f_wheel"/>
        <limit effort="1e+16" velocity="20"/>
    </joint>

    <joint name="r_f_wheel_joint" type="continuous">
        <axis rpy="0 0 0" xyz="0 0 1"/>
        <origin rpy="1.570796325 0 3.14159265" xyz="0 0 0"/>
        <parent link="r_ack_link"/>
        <child link="r_f_wheel"/>
        <limit effort="1e+16" velocity="20"/>
    </joint>

    <joint name="base_l_b_wheel_joint" type="continuous">
        <axis rpy="0 0 0" xyz="0 0 1"/>
        <origin rpy="1.570796325 0 3.14159265" xyz="-0.1795 0.19189 0.0435"/>
        <parent link="base"/>
        <child link="l_b_wheel"/>
        <limit effort="0.5" velocity="20"/>
    </joint>


    <joint name="base_r_b_wheel_joint" type="continuous">
        <axis rpy="0 0 0" xyz="0 0 1"/>
        <origin rpy="1.570796325 0 3.14159265" xyz="-0.1795 -0.19189 0.0435"/>
        <parent link="base"/>
        <child link="r_b_wheel"/>
        <!-- effort: Torque in Nm, velocity: Angula velocity in rad/s -->
        <!-- Wheel radius 0.14m, Max Speed 10km/h = 2.7778 m/s  =>  max Velocity 20rad/s -->
        <!-- Nema 17 maximal 50 Ncm -->
        <limit effort="0.5" velocity="20"/>
    </joint>

    <!--  Ackermann steering related joints. Not particularly used in case of differential drive steering (fixed)  -->
    <joint name="l_ack_link_l_f_wheel_joint" type="fixed">
        <origin rpy="0 0 0" xyz="0.1794 0.19189 0.0435"/>
        <axis rpy="0 0 0" xyz="0 0 1"/>
        <parent link="base"/>
        <child link="l_ack_link"/>
        <limit effort="1000000" lower="-0.4" upper="0.4" velocity="20"/>
    </joint>

    <joint name="r_ack_link_r_f_wheel_joint" type="fixed">
        <origin rpy="0 0 0" xyz="0.1794 -0.19189 0.0435"/>
        <axis rpy="0 0 0" xyz="0 0 1"/>
        <parent link="base"/>
        <child link="r_ack_link"/>
        <limit effort="1000000" lower="-0.4" upper="0.4" velocity="20"/>
    </joint>

    <!-- ************ Wheels friction ************ -->
    <!--  Front rigt wheel  -->
    <gazebo reference="r_f_wheel">
        <mu>0.1</mu>
        <mu2>0.1</mu2>
    </gazebo>

    <!--  Front left wheel  -->
    <gazebo reference="l_f_wheel">
        <mu>0.1</mu>
        <mu2>0.1</mu2>
    </gazebo>

    <!--  Back left wheel  -->
    <gazebo reference="l_b_wheel">
        <mu>1000.0</mu>
        <mu2>1000.0</mu2>
    </gazebo>


    <!--  Back right wheel  -->
    <gazebo reference="r_b_wheel">
        <mu>1000.0</mu>
        <mu2>1000.0</mu2>
    </gazebo>

    <!-- Plugin for Controll -->
    <gazebo>
        <plugin name="wheel_drive_controller" filename="libgazebo_ros_diff_drive.so">

            <!-- wheels -->
            <left_joint>base_l_b_wheel_joint</left_joint>
            <right_joint>base_r_b_wheel_joint</right_joint>

            <!-- kinematics -->
            <wheel_diameter>0.14</wheel_diameter>
            <wheel_separation>0.38378</wheel_separation>
            <max_wheel_torque>20</max_wheel_torque>
            <max_wheel_acceleration>1.0</max_wheel_acceleration>

            <!-- odometry  -->
            <odometry_frame>odom</odometry_frame>
            <odometry_topic>/odom</odometry_topic>
            <command_topic>cmd_vel</command_topic>
            <odometry_source>0</odometry_source>
            <robot_base_frame>base_footprint</robot_base_frame>

            <publish_odom>true</publish_odom>
            <publish_odom_tf>true</publish_odom_tf>     <!-- should be false if EKF or other algorithm is used that publishes tf -->
                                                        <!-- Changed to true because i comment out the EKF because of problem after updated -->
            <publish_wheel_tf>false</publish_wheel_tf>  <!-- should be false, otherwise the TF Tree looks weird, but then the wheel TF must be published with joint state pubisher -->
            <update_rate>50</update_rate>
        </plugin>
    </gazebo>

    <!-- *********************** joint states publisher plugin *********************   -->
    <gazebo>
        <plugin name="wheel_joint_publisher" filename="libgazebo_ros_joint_state_publisher.so">
            <ros>
                <remapping>~/out:=joint_states</remapping>
            </ros>
            <update_rate>50</update_rate>

            <!-- Front wheel rolling freely. Publish vlaue from gazebo simulation -->
            <joint_name>l_f_wheel_joint</joint_name>
            <joint_name>r_f_wheel_joint</joint_name>
            <!-- Backwheels are published here becuase if diff drive plugin publishes it, the TF-Tree is wrong -->
            <joint_name>base_l_b_wheel_joint</joint_name>
            <joint_name>base_r_b_wheel_joint</joint_name>
        </plugin>
    </gazebo>
</robot>
