<?xml version="1.0" ?>
<robot name="tas_car"
    xmlns:xacro="http://www.ros.org/wiki/xacro">

    <!-- Wheel Joints  -->
    <joint name="l_f_wheel_joint" type="continuous">
        <axis rpy="0 0 0" xyz="0 0 1"/>
        <origin rpy="1.570796325 0 3.14159265" xyz="0 0 0"/>
        <parent link="l_ack_link"/>
        <child link="l_f_wheel"/>
        <limit effort="1e+16" velocity="20"/>
    </joint>

    <joint name="r_f_wheel_joint" type="continuous">
        <axis rpy="0 0 0" xyz="0 0 1"/>
        <origin rpy="1.570796325 0 3.14159265" xyz="0 0 0"/>
        <parent link="r_ack_link"/>
        <child link="r_f_wheel"/>
        <limit effort="1e+16" velocity="20"/>
        <mimic joint="l_f_wheel_joint" multiplier="1" offset="0" />
    </joint>

    <joint name="base_l_b_wheel_joint" type="continuous">
        <axis rpy="0 0 0" xyz="0 0 1"/>
        <origin rpy="1.570796325 0 3.14159265" xyz="-0.1795 0.19189 0.0435"/>
        <parent link="base"/>
        <child link="l_b_wheel"/>
        <limit effort="0.5" velocity="20"/>
    </joint>


    <joint name="base_r_b_wheel_joint" type="continuous">
        <axis rpy="0 0 0" xyz="0 0 1"/>
        <origin rpy="1.570796325 0 3.14159265" xyz="-0.1795 -0.19189 0.0435"/>
        <parent link="base"/>
        <child link="r_b_wheel"/>
        <!-- effort: Torque in Nm, velocity: Angula velocity in rad/s -->
        <!-- Wheel radius 0.14m, Max Speed 10km/h = 2.7778 m/s  =>  max Velocity 20rad/s -->
        <!-- Nema 17 maximal 50 Ncm -->
        <limit effort="0.5" velocity="20"/>
    </joint>

    <!--  Ackermann steering related joints. Not particularly used in case of differential drive steering  -->
    <joint name="l_ack_link_l_f_wheel_joint" type="revolute">
        <origin rpy="0 0 0" xyz="0.1794 0.19189 0.0435"/>
        <axis rpy="0 0 0" xyz="0 0 1"/>
        <parent link="base"/>
        <child link="l_ack_link"/>
        <limit effort="1000000" lower="-0.4" upper="0.4" velocity="20"/>
    </joint>

    <joint name="r_ack_link_r_f_wheel_joint" type="revolute">
        <origin rpy="0 0 0" xyz="0.1794 -0.19189 0.0435"/>
        <axis rpy="0 0 0" xyz="0 0 1"/>
        <parent link="base"/>
        <child link="r_ack_link"/>
        <limit effort="1000000" lower="-0.4" upper="0.4" velocity="20"/>
        <mimic joint="l_ack_link_l_f_wheel_joint" multiplier="1" offset="0" />
    </joint>

    <!-- ************ Wheels related links and joints ************ -->
    <!--  Front rigt wheel  -->

    <gazebo reference="r_f_wheel">
        <fdir1>1 0 0</fdir1>
        <maxContacts>1</maxContacts>
        <minDepth>0.005</minDepth>
        <collision>
            <surface>
                <friction>
                    <ode>
                        <mu>100000.0</mu>
                        <mu2>100000.0</mu2>
                        <slip1>0.0</slip1>
                        <slip2>0.0</slip2>
                    </ode>
                    <torsional>
                        <coefficient>10.0</coefficient>
                        <surface_radius>1.0</surface_radius>
                        <use_patch_radius>true</use_patch_radius>
                    </torsional>
                </friction>
            </surface>
        </collision>
    </gazebo>

    <!--  Front left wheel  -->

    <gazebo reference="l_f_wheel">
        <fdir1>1 0 0</fdir1>
        <maxContacts>1</maxContacts>
        <minDepth>0.005</minDepth>
        <collision>
            <surface>
                <friction>
                    <ode>
                        <mu>100000.0</mu>
                        <mu2>100000.0</mu2>
                        <slip1>0.0</slip1>
                        <slip2>0.0</slip2>
                    </ode>
                    <torsional>
                        <coefficient>10.0</coefficient>
                        <surface_radius>1.0</surface_radius>
                        <use_patch_radius>true</use_patch_radius>
                    </torsional>
                </friction>
            </surface>
        </collision>
    </gazebo>

    <!--  Back left wheel  -->
    <gazebo reference="l_b_wheel">
        <fdir1>1 0 0</fdir1>
        <maxContacts>1</maxContacts>
        <minDepth>0.005</minDepth>
        <collision>
            <surface>
                <friction>
                    <ode>
                        <mu>100000.0</mu>
                        <mu2>100000.0</mu2>
                        <slip1>0.0</slip1>
                        <slip2>0.0</slip2>
                    </ode>
                    <torsional>
                        <coefficient>10.0</coefficient>
                        <surface_radius>1.0</surface_radius>
                        <use_patch_radius>true</use_patch_radius>
                    </torsional>
                </friction>
            </surface>
        </collision>
    </gazebo>

    <!--  Back right wheel  -->
    <gazebo reference="r_b_wheel">
        <fdir1>1 0 0</fdir1>
        <maxContacts>1</maxContacts>
        <minDepth>0.005</minDepth>
        <collision>
            <surface>
                <friction>
                    <ode>
                        <mu>100000.0</mu>
                        <mu2>100000.0</mu2>
                        <slip1>0.0</slip1>
                        <slip2>0.0</slip2>
                    </ode>
                    <torsional>
                        <coefficient>10.0</coefficient>
                        <surface_radius>1.0</surface_radius>
                        <use_patch_radius>true</use_patch_radius>
                    </torsional>
                </friction>
            </surface>
        </collision>
    </gazebo>


    <!-- Plugin for Controll -->
    <gazebo>
        <plugin name="gazebo_ros_ackermann_drive" filename="libgazebo_ros_ackermann_drive.so">
            <update_rate>100.0</update_rate>

            <!-- wheels -->
            <front_left_joint>l_f_wheel_joint</front_left_joint>
            <front_right_joint>r_f_wheel_joint</front_right_joint>
            <rear_left_joint>base_l_b_wheel_joint</rear_left_joint>
            <rear_right_joint>base_r_b_wheel_joint</rear_right_joint>
            <left_steering_joint>l_ack_link_l_f_wheel_joint</left_steering_joint>
            <right_steering_joint>r_ack_link_r_f_wheel_joint</right_steering_joint>
            <!-- <steering_wheel_joint>steering_joint</steering_wheel_joint> -->

            <!-- Max absolute steer angle for tyre in radians-->
            <!-- Any cmd_vel angular z greater than this would be capped -->
            <max_steer>0.6458</max_steer>

            <!-- Max absolute steering angle of steering wheel -->
            <max_steering_angle>7.85</max_steering_angle>

            <!-- Max absolute linear speed in m/s -->
            <max_speed>20</max_speed>

            <!-- PID tuning -->
            <left_steering_pid_gain>1500 0 1</left_steering_pid_gain>
            <left_steering_i_range>0 0</left_steering_i_range>
            <right_steering_pid_gain>1500 0 1</right_steering_pid_gain>
            <right_steering_i_range>0 0</right_steering_i_range>
            <linear_velocity_pid_gain>1000 0 1</linear_velocity_pid_gain>
            <linear_velocity_i_range>0 0</linear_velocity_i_range>

            <!-- output -->
            <publish_odom>true</publish_odom>
            <publish_odom_tf>true</publish_odom_tf>
            <publish_wheel_tf>true</publish_wheel_tf>
            <publish_distance>true</publish_distance>

            <odometry_frame>odom</odometry_frame>
            <robot_base_frame>base_footprint</robot_base_frame>

            <!-- <ros>
                <namespace>demo</namespace>
                <remapping>cmd_vel:=cmd_demo</remapping>
                <remapping>odom:=odom_demo</remapping>
                <remapping>distance:=distance_demo</remapping>
            </ros> -->

        </plugin>

    </gazebo>


</robot>
